<?xml version="1.0" encoding="utf-8"?>
<!-- This URDF was automatically created by SolidWorks to URDF Exporter! Originally created by Stephen Brawner (brawner@gmail.com) 
     Commit Version: 1.5.1-0-g916b5db  Build Version: 1.5.7152.31018
     For more information, please see http://wiki.ros.org/sw_urdf_exporter -->
<robot
  name="finger">
  <link name="world"/>
  <joint name="fixed" type="fixed">
    <parent link="world"/>
    <child link="base_link"/>
  </joint>
  <link
    name="base_link">
    <inertial>
      <origin
        xyz="0.0014547 -4.3368E-18 0.030405"
        rpy="0 0 0" />
      <mass
        value="0.21168" />
      <inertia
        ixx="0.00023035"
        ixy="-3.7311E-21"
        ixz="-3.4957E-05"
        iyy="0.00033399"
        iyz="-1.4134E-20"
        izz="0.00025833" />
    </inertial>
    <visual>
      <origin
        xyz="0 0 0"
        rpy="0 0 0" />
      <geometry>
        <mesh
          filename="package://finger/meshes/base_link.STL" />
      </geometry>
      <material
        name="">
        <color
          rgba="1 1 1 1" />
      </material>
    </visual>
    <collision>
      <origin
        xyz="0 0 0"
        rpy="0 0 0" />
      <geometry>
        <mesh
          filename="package://finger/meshes/base_link.STL" />
      </geometry>
    </collision>
  </link>
  <link
    name="finger_Link2">
    <inertial>
      <origin
        xyz="-0.01025 6.9389E-18 0.064"
        rpy="0 0 0" />
      <mass
        value="0.06" />
      <inertia
        ixx="4.604E-05"
        ixy="-1.175E-21"
        ixz="-8.085E-06"
        iyy="4.6086E-05"
        iyz="-4.3195E-21"
        izz="9.0463E-06" />
    </inertial>
    <visual>
      <origin
        xyz="0 0 0"
        rpy="0 0 0" />
      <geometry>
        <mesh
          filename="package://finger/meshes/finger_Link2.STL" />
      </geometry>
      <material
        name="">
        <color
          rgba="1 1 1 1" />
      </material>
    </visual>
    <collision>
      <origin
        xyz="0 0 0"
        rpy="0 0 0" />
      <geometry>
        <mesh
          filename="package://finger/meshes/finger_Link2.STL" />
      </geometry>
    </collision>
  </link>
  <joint
    name="finger_joint"
    type="prismatic">
    <origin
      xyz="0 0 0"
      rpy="0 0 0" />
    <parent
      link="base_link" />
    <child
      link="finger_Link2" />
    <axis
      xyz="-1 0 0" />
    <limit
      lower="-1"
      upper="1"
      effort="5"
      velocity="9" />
  </joint>
</robot>