<?xml version="1.0"?>
<robot name="armt" xmlns:xacro="http://wiki.ros.org/xacro">

  <xacro:include filename="$(find arm_hand)/urdf/armt.transmission.xacro" />
  <xacro:include filename="$(find arm_hand)/urdf/armt.gazebo.xacro" />

  <xacro:macro name="cylinder_inertial" params="radius length mass *origin">
    <inertial>
      <mass value="${mass}" />
      <xacro:insert_block name="origin" />
      <inertia ixx="${0.0833333 * mass * (3 * radius * radius + length * length)}" ixy="0.0" ixz="0.0"
        iyy="${0.0833333 * mass * (3 * radius * radius + length * length)}" iyz="0.0"
        izz="${0.5 * mass * radius * radius}" />
    </inertial>
  </xacro:macro>

  <xacro:macro name="armt_robot" params="prefix joint_limited
    joint1_lower_limit:=${-pi}      joint1_upper_limit:=${pi}
    joint2_lower_limit:=${-pi/2}    joint2_upper_limit:=${pi/2}
    joint3_lower_limit:=${-pi}      joint3_upper_limit:=${pi}
    joint4_lower_limit:=${-pi/2}    joint4_upper_limit:=${pi/2}
    joint5_lower_limit:=${-pi}      joint5_upper_limit:=${pi}
    joint6_lower_limit:=${-pi/2}    joint6_upper_limit:=${pi/2}
    joint7_lower_limit:=${-pi*10}   joint7_upper_limit:=${pi*10}
    transmission_hw_interface:=hardware_interface/PositionJointInterface
    safety_limits:=false safety_pos_margin:=0.15
    safety_k_position:=20">

    <!-- Inertia parameters -->
    <xacro:property name="base_mass"      value="4.0" />  <!-- This mass might be incorrect -->
    <xacro:property name="joint1_mass"    value="3.7000" />
    <xacro:property name="joint2_mass"    value="8.3930" />
    <xacro:property name="joint3_mass"    value="2.2750" />
    <xacro:property name="joint4_mass"    value="1.2190" />
    <xacro:property name="joint5_mass"    value="1.2190" />
    <xacro:property name="joint6_mass"    value="0.1879" />
    <xacro:property name="joint7_mass"    value="0.1879" />

    <xacro:property name="joint1_cog" value="0.0 0.00193 -0.02561" />
    <xacro:property name="joint2_cog" value="0.0 -0.024201 0.2125" />
    <xacro:property name="joint3_cog" value="0.0 0.0265 0.11993" />
    <xacro:property name="joint4_cog" value="0.0 0.110949 0.01634" />
    <xacro:property name="joint5_cog" value="0.0 0.0018 0.11099" />
    <xacro:property name="joint6_cog" value="0.0 0.001159 0.0" />
    <xacro:property name="joint7_cog" value="0.0 0.001159 0.0" />

    <!-- Kinematic model -->
    <!-- Properties from urcontrol.conf -->
    <!--
      DH for UR5:
      a = [0.00000, -0.42500, -0.39225,  0.00000,  0.00000,  0.0000]
      d = [0.089159,  0.00000,  0.00000,  0.10915,  0.09465,  0.0823]
      alpha = [ 1.570796327, 0, 0, 1.570796327, -1.570796327, 0 ]
      q_home_offset = [0, -1.570796327, 0, -1.570796327, 0, 0]
      joint_direction = [-1, -1, 1, 1, 1, 1]
      mass = [3.7000, 8.3930, 2.2750, 1.2190, 1.2190, 0.1879]
      center_of_mass = [ [0, -0.02561, 0.00193], [0.2125, 0, 0.11336], [0.11993, 0.0, 0.0265], [0, -0.0018, 0.01634], [0, 0.0018,0.01634], [0, 0, -0.001159] ]
    -->
    <xacro:property name="d1" value="0.089159" />
    <xacro:property name="d2" value="-0.42500" />
    <xacro:property name="d3" value="-0.39225" />
    <xacro:property name="d4" value="0.10915" />
    <xacro:property name="d5" value="0.09465" />
    <xacro:property name="d6" value="0.0823" />
    <xacro:property name="d7" value="0.0823" />

    <!-- link lengths used in model -->
    <xacro:property name="joint1_height" value="${d1}" />
    <xacro:property name="joint2_length" value="${d2}" />
    <xacro:property name="joint3_length" value="${d3}" />
    <xacro:property name="joint4_length" value="${d4 }" />
    <xacro:property name="joint5_length" value="${d5}" />
    <xacro:property name="joint6_length" value="${d6}" />
    <xacro:property name="joint6_length" value="${d7}" />
    <!--property name="joint1_height" value="0.089159" /-->
    <!--property name="joint1_offset" value="0.13585" /-->  <!-- joint1_offset - joint3_offset + joint4_length = 0.10915 -->
    <!--property name="joint2_length" value="0.42500" /-->
    <!--property name="joint3_offset" value="0.1197" /-->       <!-- CAD measured -->
    <!--property name="joint3_length" value="0.39225" /-->
    <!--property name="joint4_length" value="0.093" /-->     <!-- CAD measured -->
    <!--property name="joint5_length" value="0.09465" /-->   <!-- In CAD this distance is 0.930, but in the spec it is 0.09465 -->
    <!--property name="joint6_length" value="0.0823" /-->

    <xacro:property name="joint1_radius" value="0.060" />   <!-- manually measured -->
    <xacro:property name="joint2_radius" value="0.054" />  <!-- manually measured -->
    <xacro:property name="joint3_radius" value="0.060" />      <!-- manually measured -->
    <xacro:property name="joint3_radius" value="0.040" />    <!-- manually measured -->
    <xacro:property name="wrist_radius" value="0.045" />      <!-- manually measured -->

    <link
    name="base_link">
    <inertial>
      <origin
        xyz="1.1573E-17 0.038378 -6.6824E-18"
        rpy="0 0 0" />
      <mass
        value="1.52905" />
      <inertia
        ixx="0.0013499"
        ixy="1.8086E-19"
        ixz="3.6213E-19"
        iyy="0.0018032"
        iyz="-9.8905E-19"
        izz="0.0013499" />
    </inertial>
    <visual>
      <origin
        xyz="0 0 0"
        rpy="0 0 0" />
      <geometry>
        <mesh
          filename="package://arm_hand/meshes/base_link.STL" />
      </geometry>
      <material
        name="">
        <color
          rgba="1 1 1 1" />
      </material>
    </visual>
    <collision>
      <origin
        xyz="0 0 0"
        rpy="0 0 0" />
      <geometry>
        <mesh
          filename="package://arm_hand/meshes/base_link.STL" />
      </geometry>
    </collision>
  </link>
  <link
    name="link1">
    <inertial>
      <origin
        xyz="0.00010945 0.018543 0.12833"
        rpy="0 0 0" />
      <mass
        value="1.60706" />
      <inertia
        ixx="0.0052527"
        ixy="1.2302E-06"
        ixz="6.2782E-06"
        iyy="0.0052194"
        iyz="-0.001062"
        izz="0.0016215" />
    </inertial>
    <visual>
      <origin
        xyz="0 0 0"
        rpy="0 0 0" />
      <geometry>
        <mesh
          filename="package://arm_hand/meshes/link1.STL" />
      </geometry>
      <material
        name="">
        <color
          rgba="1 1 1 1" />
      </material>
    </visual>
    <collision>
      <origin
        xyz="0 0 0"
        rpy="0 0 0" />
      <geometry>
        <mesh
          filename="package://arm_hand/meshes/link1.STL" />
      </geometry>
    </collision>
  </link>
  <joint
    name="joint1"
    type="revolute">
    <origin
      xyz="0 0 0.093"
      rpy="0 0 0" />
    <parent
      link="base_link" />
    <child
      link="link1" />
    <axis
      xyz="0 0 1" />
      <limit
        lower="-3"
        upper="3"
        effort="100"
        velocity="2" />
  </joint>
  <link
    name="link2">
    <inertial>
      <origin
        xyz="0.00011075 -0.017942 0.0078663"
        rpy="0 0 0" />
      <mass
        value="1.60706" />
      <inertia
        ixx="0.0024049"
        ixy="-1.1871E-06"
        ixz="2.9893E-06"
        iyy="0.0021682"
        iyz="2.4034E-06"
        izz="0.0018251" />
    </inertial>
    <visual>
      <origin
        xyz="0 0 0"
        rpy="0 0 0" />
      <geometry>
        <mesh
          filename="package://arm_hand/meshes/link2.STL" />
      </geometry>
      <material
        name="">
        <color
          rgba="0.79216 0.81961 0.93333 1" />
      </material>
    </visual>
    <collision>
      <origin
        xyz="0 0 0"
        rpy="0 0 0" />
      <geometry>
        <mesh
          filename="package://arm_hand/meshes/link2.STL" />
      </geometry>
    </collision>
  </link>
  <joint
    name="joint2"
    type="revolute">
    <origin
      xyz="0 0 0.2305"
      rpy="-1.5708 0 3.1416" />
    <parent
      link="link1" />
    <child
      link="link2" />
    <axis
      xyz="0 0 1" />
    <limit
      lower="-1.5708"
      upper="1.5708"
      effort="100"
      velocity="2" />
  </joint>
  <link
    name="link3">
    <inertial>
      <origin
        xyz="0.00012135 0.016856 0.12027"
        rpy="0 0 0" />
      <mass
        value="1.55026" />
      <inertia
        ixx="0.0046713"
        ixy="1.1239E-06"
        ixz="5.7279E-06"
        iyy="0.0045964"
        iyz="-0.00093576"
        izz="0.0014215" />
    </inertial>
    <visual>
      <origin
        xyz="0 0 0"
        rpy="0 0 0" />
      <geometry>
        <mesh
          filename="package://arm_hand/meshes/link3.STL" />
      </geometry>
      <material
        name="">
        <color
          rgba="1 1 1 1" />
      </material>
    </visual>
    <collision>
      <origin
        xyz="0 0 0"
        rpy="0 0 0" />
      <geometry>
        <mesh
          filename="package://arm_hand/meshes/link3.STL" />
      </geometry>
    </collision>
  </link>
  <joint
    name="joint3"
    type="revolute">
    <origin
      xyz="0 -0.0875 0"
      rpy="-1.5708 0 -3.1416" />
    <parent
      link="link2" />
    <child
      link="link3" />
    <axis
      xyz="0 0 1" />
      <limit
        lower="-3"
        upper="3"
        effort="100"
        velocity="2" />
  </joint>
  <link
    name="link4">
    <inertial>
      <origin
        xyz="0.00012809 -0.012483 0.0052641"
        rpy="0 0 0" />
      <mass
        value="1.52212" />
      <inertia
        ixx="0.0019651"
        ixy="-8.33E-07"
        ixz="2.8077E-06"
        iyy="0.0017984"
        iyz="2.5495E-05"
        izz="0.0013529" />
    </inertial>
    <visual>
      <origin
        xyz="0 0 0"
        rpy="0 0 0" />
      <geometry>
        <mesh
          filename="package://arm_hand/meshes/link4.STL" />
      </geometry>
      <material
        name="">
        <color
          rgba="1 1 1 1" />
      </material>
    </visual>
    <collision>
      <origin
        xyz="0 0 0"
        rpy="0 0 0" />
      <geometry>
        <mesh
          filename="package://arm_hand/meshes/link4.STL" />
      </geometry>
    </collision>
  </link>
  <joint
    name="joint4"
    type="revolute">
    <origin
      xyz="0 0 0.2285"
      rpy="-1.5708 0 3.1416" />
    <parent
      link="link3" />
    <child
      link="link4" />
    <axis
      xyz="0 0 1" />
    <limit
      lower="-1.5708"
      upper="1.5708"
      effort="100"
      velocity="2" />
  </joint>
  <link
    name="link5">
    <inertial>
      <origin
        xyz="1.2142E-07 0.015081 0.10577"
        rpy="0 0 0" />
      <mass
        value="1.33383" />
      <inertia
        ixx="0.0021595"
        ixy="-1.4296E-09"
        ixz="9.1759E-11"
        iyy="0.0020793"
        iyz="-0.00045807"
        izz="0.00059386" />
    </inertial>
    <visual>
      <origin
        xyz="0 0 0"
        rpy="0 0 0" />
      <geometry>
        <mesh
          filename="package://arm_hand/meshes/link5.STL" />
      </geometry>
      <material
        name="">
        <color
          rgba="1 1 1 1" />
      </material>
    </visual>
    <collision>
      <origin
        xyz="0 0 0"
        rpy="0 0 0" />
      <geometry>
        <mesh
          filename="package://arm_hand/meshes/link5.STL" />
      </geometry>
    </collision>
  </link>
  <joint
    name="joint5"
    type="revolute">
    <origin
      xyz="0 -0.0835 0"
      rpy="-1.5708 0 3.1416" />
    <parent
      link="link4" />
    <child
      link="link5" />
    <axis
      xyz="0 0 1" />
      <limit
        lower="-3"
        upper="3"
        effort="100"
        velocity="2" />
  </joint>
  <link
    name="link6">
    <inertial>
      <origin
        xyz="5.949E-08 -0.052988 0.0036397"
        rpy="0 0 0" />
      <mass
        value="1.48339" />
      <inertia
        ixx="0.0030887"
        ixy="-7.6314E-09"
        ixz="-1.9399E-09"
        iyy="0.0010669"
        iyz="-7.2904E-05"
        izz="0.0027189" />
    </inertial>
    <visual>
      <origin
        xyz="0 0 0"
        rpy="0 0 0" />
      <geometry>
        <mesh
          filename="package://arm_hand/meshes/link6.STL" />
      </geometry>
      <material
        name="">
        <color
          rgba="1 1 1 1" />
      </material>
    </visual>
    <collision>
      <origin
        xyz="0 0 0"
        rpy="0 0 0" />
      <geometry>
        <mesh
          filename="package://arm_hand/meshes/link6.STL" />
      </geometry>
    </collision>
  </link>
  <joint
    name="joint6"
    type="revolute">
    <origin
      xyz="0 0 0.201"
      rpy="-1.5708 0 3.1416" />
    <parent
      link="link5" />
    <child
      link="link6" />
    <axis
      xyz="0 0 1" />
    <limit
      lower="-1.5708"
      upper="1.5708"
      effort="100"
      velocity="10" />
  </joint>
  <link
    name="link7">
    <inertial>
      <origin
        xyz="-9.4726E-16 1.3048E-18 0.0069942"
        rpy="0 0 0" />
      <mass
        value="1.084854" />
      <inertia
        ixx="3.4215E-05"
        ixy="-1.7999E-21"
        ixz="-5.7516E-21"
        iyy="3.4215E-05"
        iyz="-2.3556E-22"
        izz="6.7596E-05" />
    </inertial>
    <visual>
      <origin
        xyz="0 0 0"
        rpy="0 0 0" />
      <geometry>
        <mesh
          filename="package://arm_hand/meshes/link7.STL" />
      </geometry>
      <material
        name="">
        <color
          rgba="0.89804 0.91765 0.92941 1" />
      </material>
    </visual>
    <collision>
      <origin
        xyz="0 0 0"
        rpy="0 0 0" />
      <geometry>
        <mesh
          filename="package://arm_hand/meshes/link7.STL" />
      </geometry>
    </collision>
  </link>
  <joint
    name="joint7"
    type="revolute">
    <origin
      xyz="0 -0.1905 0"
      rpy="-1.5708 3.1416 3.1416" />
    <parent
      link="link6" />
    <child
      link="link7" />
    <axis
      xyz="0 0 1" />
      <limit
        lower="-3"
        upper="3"
        effort="100"
        velocity="2" />
  </joint>

    <xacro:armt_arm_transmission prefix="${prefix}" hw_interface="${transmission_hw_interface}" />
    <xacro:armt_arm_gazebo prefix="${prefix}" />

    <!-- Frame coincident with all-zeros TCP on UR controller -->

  </xacro:macro>
</robot>
